Workbook

Sheet для 2 треугольников
R2: ρ | S2: 1 | W2: пробуем посчитать турбулентность
R3: Δt | S3: 0.03
D4: X | E4: Y | R4: γ | S4: 0.1 | U4: вязкость
C5: 1 | D5: 0 | E5: 0
C6: 2 | D6: 1 | E6: 0
C7: 3 | D7: 1 | E7: 1
C8: 4 | D8: 0 | E8: 1
B10: 1 треугольник | F10: X | G10: Y
E11: 1 | F11: =D5 -> 0 | G11: =E5 -> 0
B12: одна точка интегрирования | E12: 2 | F12: =D6 -> 1 | G12: =E6 -> 0
E13: 3 | F13: =D7 -> 1 | G13: =E7 -> 1
B14: ось | C14: координата т. интегр. | E14: производные функции формы | J14: матрица Якоби [J] | N14: detJ | P14: detJ* коэф | R14: один раз умножаем!!!!! | U14: {J]-1
B15: ξ | C15: =1/3 -> 0.33333333 | E15: -1 | F15: 1 | G15: 0 | J15: {=MMULT(E15:G16,F11:G13)} -> 1 | K15: 0 | N15: =MDETERM(J15:K16) -> 1 | P15: =N15*0.5 -> 0.5 | Q15: S | U15: {=MINVERSE(J15:K16)} -> 1 | V15: 0
B16: η | C16: =1/3 -> 0.33333333 | E16: -1 | F16: 0 | G16: 1 | J16: 1 | K16: 1 | U16: -1 | V16: 1
E19: N1 | F19: N2 | G19: N3 | I19: NT | K19: NT*N | O19: NT*N*detJ*коэф
E20: =1-C15-C16 -> 0.33333333 | F20: =C15 -> 0.33333333 | G20: =C16 -> 0.33333333 | I20: {=TRANSPOSE(E20:G20)} -> 0.33333333 | K20: {=MMULT(I20:I22,E20:G20)} -> 0.11111111 | L20: 0.11111111 | M20: 0.11111111 | O20: =K20*$P$15 -> 0.055555556 | P20: =L20*$P$15 -> 0.055555556 | Q20: =M20*$P$15 -> 0.055555556
I21: 0.33333333 | K21: 0.11111111 | L21: 0.11111111 | M21: 0.11111111 | O21: =K21*$P$15 -> 0.055555556 | P21: =L21*$P$15 -> 0.055555556 | Q21: =M21*$P$15 -> 0.055555556
E22: =SUM(E20:G20) -> 1 | I22: 0.33333333 | K22: 0.11111111 | L22: 0.11111111 | M22: 0.11111111 | O22: =K22*$P$15 -> 0.055555556 | P22: =L22*$P$15 -> 0.055555556 | Q22: =M22*$P$15 -> 0.055555556
O23: трансп dNi/dx, dNi/dy | V23: K1
E24: {=MMULT($U$15:$V$16,E15:E16)} -> -1 | F24: {=MMULT($U$15:$V$16,F15:F16)} -> 1 | G24: {=MMULT($U$15:$V$16,G15:G16)} -> 0 | O24: {=TRANSPOSE(E24:G25)} -> -1 | P24: 0 | R24: {=MMULT(O24:P26,E24:G25)} -> 1 | S24: -1 | T24: 0 | V24: =R24*$P$15 -> 0.5 | W24: =S24*$P$15 -> -0.5 | X24: =T24*$P$15 -> 0
E25: 0 | F25: -1 | G25: 1 | O25: 1 | P25: -1 | R25: -1 | S25: 2 | T25: -1 | V25: =R25*$P$15 -> -0.5 | W25: =S25*$P$15 -> 1 | X25: =T25*$P$15 -> -0.5
O26: 0 | P26: 1 | R26: 0 | S26: -1 | T26: 1 | V26: =R26*$P$15 -> 0 | W26: =S26*$P$15 -> -0.5 | X26: =T26*$P$15 -> 0.5
E27: B | L27: BT | P27: BT*B | W27: BT*B*det[J]*коэф
E28: =E24 -> -1 | F28: 0 | G28: =F24 -> 1 | H28: 0 | I28: =G24 -> 0 | J28: 0 | L28: {=TRANSPOSE(E28:J30)} -> -1 | M28: 0 | N28: 0 | P28: {=MMULT(L28:N33,E28:J30)} -> 1 | Q28: 0 | R28: -1 | S28: 0 | T28: 0 | U28: 0 | W28: =P28*$P$15 -> 0.5 | X28: =Q28*$P$15 -> 0 | Y28: =R28*$P$15 -> -0.5 | Z28: =S28*$P$15 -> 0 | AA28: =T28*$P$15 -> 0 | AB28: =U28*$P$15 -> 0
E29: 0 | F29: =E25 -> 0 | G29: 0 | H29: =F25 -> -1 | I29: 0 | J29: =G25 -> 1 | L29: 0 | M29: 0 | N29: -1 | P29: 0 | Q29: 1 | R29: 1 | S29: -1 | T29: -1 | U29: 0 | W29: =P29*$P$15 -> 0 | X29: =Q29*$P$15 -> 0.5 | Y29: =R29*$P$15 -> 0.5 | Z29: =S29*$P$15 -> -0.5 | AA29: =T29*$P$15 -> -0.5 | AB29: =U29*$P$15 -> 0
E30: =E25 -> 0 | F30: =E24 -> -1 | G30: =F25 -> -1 | H30: =F24 -> 1 | I30: =G25 -> 1 | J30: =G24 -> 0 | L30: 1 | M30: 0 | N30: -1 | P30: -1 | Q30: 1 | R30: 2 | S30: -1 | T30: -1 | U30: 0 | W30: =P30*$P$15 -> -0.5 | X30: =Q30*$P$15 -> 0.5 | Y30: =R30*$P$15 -> 1 | Z30: =S30*$P$15 -> -0.5 | AA30: =T30*$P$15 -> -0.5 | AB30: =U30*$P$15 -> 0
L31: 0 | M31: -1 | N31: 1 | P31: 0 | Q31: -1 | R31: -1 | S31: 2 | T31: 1 | U31: -1 | W31: =P31*$P$15 -> 0 | X31: =Q31*$P$15 -> -0.5 | Y31: =R31*$P$15 -> -0.5 | Z31: =S31*$P$15 -> 1 | AA31: =T31*$P$15 -> 0.5 | AB31: =U31*$P$15 -> -0.5
L32: 0 | M32: 0 | N32: 1 | P32: 0 | Q32: -1 | R32: -1 | S32: 1 | T32: 1 | U32: 0 | W32: =P32*$P$15 -> 0 | X32: =Q32*$P$15 -> -0.5 | Y32: =R32*$P$15 -> -0.5 | Z32: =S32*$P$15 -> 0.5 | AA32: =T32*$P$15 -> 0.5 | AB32: =U32*$P$15 -> 0
L33: 0 | M33: 1 | N33: 0 | P33: 0 | Q33: 0 | R33: 0 | S33: -1 | T33: 0 | U33: 1 | W33: =P33*$P$15 -> 0 | X33: =Q33*$P$15 -> 0 | Y33: =R33*$P$15 -> 0 | Z33: =S33*$P$15 -> -0.5 | AA33: =T33*$P$15 -> 0 | AB33: =U33*$P$15 -> 0.5
B36: 2 треугольник | F36: X | G36: Y
E37: 1 | F37: =D5 -> 0 | G37: =E5 -> 0
B38: одна точка интегрирования | E38: 3 | F38: =D7 -> 1 | G38: =E7 -> 1
E39: 4 | F39: =D8 -> 0 | G39: =E8 -> 1
B40: ось | C40: координата т. интегр. | E40: производные функции формы | J40: матрица Якоби [J] | N40: detJ | P40: detJ* коэф | R40: один раз умножаем!!!!! | U40: {J]-1
B41: ξ | C41: =1/3 -> 0.33333333 | E41: -1 | F41: 1 | G41: 0 | J41: {=MMULT(E41:G42,F37:G39)} -> 1 | K41: 1 | N41: =MDETERM(J41:K42) -> 1 | P41: =N41*0.5 -> 0.5 | Q41: S | U41: {=MINVERSE(J41:K42)} -> 1 | V41: -1
B42: η | C42: =1/3 -> 0.33333333 | E42: -1 | F42: 0 | G42: 1 | J42: 0 | K42: 1 | U42: 0 | V42: 1
E45: N1 | F45: N2 | G45: N3 | I45: NT | K45: NT*N | O45: NT*N*detJ*коэф
E46: =1-C41-C42 -> 0.33333333 | F46: =C41 -> 0.33333333 | G46: =C42 -> 0.33333333 | I46: {=TRANSPOSE(E46:G46)} -> 0.33333333 | K46: {=MMULT(I46:I48,E46:G46)} -> 0.11111111 | L46: 0.11111111 | M46: 0.11111111 | O46: =K46*$P$15 -> 0.055555556 | P46: =L46*$P$15 -> 0.055555556 | Q46: =M46*$P$15 -> 0.055555556
I47: 0.33333333 | K47: 0.11111111 | L47: 0.11111111 | M47: 0.11111111 | O47: =K47*$P$15 -> 0.055555556 | P47: =L47*$P$15 -> 0.055555556 | Q47: =M47*$P$15 -> 0.055555556
E48: =SUM(E46:G46) -> 1 | I48: 0.33333333 | K48: 0.11111111 | L48: 0.11111111 | M48: 0.11111111 | O48: =K48*$P$15 -> 0.055555556 | P48: =L48*$P$15 -> 0.055555556 | Q48: =M48*$P$15 -> 0.055555556
...

Sheet 2 шаг 
R2: ρ | S2: 1
R3: Δt | S3: 0.03
D4: X | E4: Y | R4: γ | S4: 0.1 | U4: вязкость
C5: 1 | D5: 0 | E5: 0
C6: 2 | D6: 1 | E6: 0
C7: 3 | D7: 1 | E7: 1
C8: 4 | D8: 0 | E8: 1
B10: 1 треугольник | F10: X | G10: Y
E11: 1 | F11: =D5 -> 0 | G11: =E5 -> 0
B12: одна точка интегрирования | E12: 2 | F12: =D6 -> 1 | G12: =E6 -> 0
E13: 3 | F13: =D7 -> 1 | G13: =E7 -> 1
B14: ось | C14: координата т. интегр. | E14: производные функции формы | J14: матрица Якоби [J] | N14: detJ | P14: detJ* коэф | R14: один раз умножаем!!!!! | U14: {J]-1
B15: ξ | C15: =1/3 -> 0.33333333 | E15: -1 | F15: 1 | G15: 0 | J15: {=MMULT(E15:G16,F11:G13)} -> 1 | K15: 0 | N15: =MDETERM(J15:K16) -> 1 | P15: =N15*0.5 -> 0.5 | Q15: S | U15: {=MINVERSE(J15:K16)} -> 1 | V15: 0
B16: η | C16: =1/3 -> 0.33333333 | E16: -1 | F16: 0 | G16: 1 | J16: 1 | K16: 1 | U16: -1 | V16: 1
E19: N1 | F19: N2 | G19: N3 | I19: NT | K19: NT*N | O19: NT*N*detJ*коэф
E20: =1-C15-C16 -> 0.33333333 | F20: =C15 -> 0.33333333 | G20: =C16 -> 0.33333333 | I20: {=TRANSPOSE(E20:G20)} -> 0.33333333 | K20: {=MMULT(I20:I22,E20:G20)} -> 0.11111111 | L20: 0.11111111 | M20: 0.11111111 | O20: =K20*$P$15 -> 0.055555556 | P20: =L20*$P$15 -> 0.055555556 | Q20: =M20*$P$15 -> 0.055555556
I21: 0.33333333 | K21: 0.11111111 | L21: 0.11111111 | M21: 0.11111111 | O21: =K21*$P$15 -> 0.055555556 | P21: =L21*$P$15 -> 0.055555556 | Q21: =M21*$P$15 -> 0.055555556
E22: =SUM(E20:G20) -> 1 | I22: 0.33333333 | K22: 0.11111111 | L22: 0.11111111 | M22: 0.11111111 | O22: =K22*$P$15 -> 0.055555556 | P22: =L22*$P$15 -> 0.055555556 | Q22: =M22*$P$15 -> 0.055555556
V23: K1
E24: {=MMULT($U$15:$V$16,E15:E16)} -> -1 | F24: {=MMULT($U$15:$V$16,F15:F16)} -> 1 | G24: {=MMULT($U$15:$V$16,G15:G16)} -> 0 | O24: {=TRANSPOSE(E24:G25)} -> -1 | P24: 0 | R24: {=MMULT(O24:P26,E24:G25)} -> 1 | S24: -1 | T24: 0 | V24: =R24*$P$15 -> 0.5 | W24: =S24*$P$15 -> -0.5 | X24: =T24*$P$15 -> 0
E25: 0 | F25: -1 | G25: 1 | O25: 1 | P25: -1 | R25: -1 | S25: 2 | T25: -1 | V25: =R25*$P$15 -> -0.5 | W25: =S25*$P$15 -> 1 | X25: =T25*$P$15 -> -0.5
O26: 0 | P26: 1 | R26: 0 | S26: -1 | T26: 1 | V26: =R26*$P$15 -> 0 | W26: =S26*$P$15 -> -0.5 | X26: =T26*$P$15 -> 0.5
E27: B | L27: BT | P27: BT*B | W27: BT*B*det[J]*коэф
E28: =E24 -> -1 | F28: 0 | G28: =F24 -> 1 | H28: 0 | I28: =G24 -> 0 | J28: 0 | L28: {=TRANSPOSE(E28:J30)} -> -1 | M28: 0 | N28: 0 | P28: {=MMULT(L28:N33,E28:J30)} -> 1 | Q28: 0 | R28: -1 | S28: 0 | T28: 0 | U28: 0 | W28: =P28*$P$15 -> 0.5 | X28: =Q28*$P$15 -> 0 | Y28: =R28*$P$15 -> -0.5 | Z28: =S28*$P$15 -> 0 | AA28: =T28*$P$15 -> 0 | AB28: =U28*$P$15 -> 0
E29: 0 | F29: =E25 -> 0 | G29: 0 | H29: =F25 -> -1 | I29: 0 | J29: =G25 -> 1 | L29: 0 | M29: 0 | N29: -1 | P29: 0 | Q29: 1 | R29: 1 | S29: -1 | T29: -1 | U29: 0 | W29: =P29*$P$15 -> 0 | X29: =Q29*$P$15 -> 0.5 | Y29: =R29*$P$15 -> 0.5 | Z29: =S29*$P$15 -> -0.5 | AA29: =T29*$P$15 -> -0.5 | AB29: =U29*$P$15 -> 0
E30: =E25 -> 0 | F30: =E24 -> -1 | G30: =F25 -> -1 | H30: =F24 -> 1 | I30: =G25 -> 1 | J30: =G24 -> 0 | L30: 1 | M30: 0 | N30: -1 | P30: -1 | Q30: 1 | R30: 2 | S30: -1 | T30: -1 | U30: 0 | W30: =P30*$P$15 -> -0.5 | X30: =Q30*$P$15 -> 0.5 | Y30: =R30*$P$15 -> 1 | Z30: =S30*$P$15 -> -0.5 | AA30: =T30*$P$15 -> -0.5 | AB30: =U30*$P$15 -> 0
L31: 0 | M31: -1 | N31: 1 | P31: 0 | Q31: -1 | R31: -1 | S31: 2 | T31: 1 | U31: -1 | W31: =P31*$P$15 -> 0 | X31: =Q31*$P$15 -> -0.5 | Y31: =R31*$P$15 -> -0.5 | Z31: =S31*$P$15 -> 1 | AA31: =T31*$P$15 -> 0.5 | AB31: =U31*$P$15 -> -0.5
L32: 0 | M32: 0 | N32: 1 | P32: 0 | Q32: -1 | R32: -1 | S32: 1 | T32: 1 | U32: 0 | W32: =P32*$P$15 -> 0 | X32: =Q32*$P$15 -> -0.5 | Y32: =R32*$P$15 -> -0.5 | Z32: =S32*$P$15 -> 0.5 | AA32: =T32*$P$15 -> 0.5 | AB32: =U32*$P$15 -> 0
L33: 0 | M33: 1 | N33: 0 | P33: 0 | Q33: 0 | R33: 0 | S33: -1 | T33: 0 | U33: 1 | W33: =P33*$P$15 -> 0 | X33: =Q33*$P$15 -> 0 | Y33: =R33*$P$15 -> 0 | Z33: =S33*$P$15 -> -0.5 | AA33: =T33*$P$15 -> 0 | AB33: =U33*$P$15 -> 0.5
B36: 2 треугольник | F36: X | G36: Y
E37: 1 | F37: =D5 -> 0 | G37: =E5 -> 0
B38: одна точка интегрирования | E38: 3 | F38: =D7 -> 1 | G38: =E7 -> 1
E39: 4 | F39: =D8 -> 0 | G39: =E8 -> 1
B40: ось | C40: координата т. интегр. | E40: производные функции формы | J40: матрица Якоби [J] | N40: detJ | P40: detJ* коэф | R40: один раз умножаем!!!!! | U40: {J]-1
B41: ξ | C41: =1/3 -> 0.33333333 | E41: -1 | F41: 1 | G41: 0 | J41: {=MMULT(E41:G42,F37:G39)} -> 1 | K41: 1 | N41: =MDETERM(J41:K42) -> 1 | P41: =N41*0.5 -> 0.5 | Q41: S | U41: {=MINVERSE(J41:K42)} -> 1 | V41: -1
B42: η | C42: =1/3 -> 0.33333333 | E42: -1 | F42: 0 | G42: 1 | J42: 0 | K42: 1 | U42: 0 | V42: 1
E45: N1 | F45: N2 | G45: N3 | I45: NT | K45: NT*N | O45: NT*N*detJ*коэф
E46: =1-C41-C42 -> 0.33333333 | F46: =C41 -> 0.33333333 | G46: =C42 -> 0.33333333 | I46: {=TRANSPOSE(E46:G46)} -> 0.33333333 | K46: {=MMULT(I46:I48,E46:G46)} -> 0.11111111 | L46: 0.11111111 | M46: 0.11111111 | O46: =K46*$P$15 -> 0.055555556 | P46: =L46*$P$15 -> 0.055555556 | Q46: =M46*$P$15 -> 0.055555556
I47: 0.33333333 | K47: 0.11111111 | L47: 0.11111111 | M47: 0.11111111 | O47: =K47*$P$15 -> 0.055555556 | P47: =L47*$P$15 -> 0.055555556 | Q47: =M47*$P$15 -> 0.055555556
E48: =SUM(E46:G46) -> 1 | I48: 0.33333333 | K48: 0.11111111 | L48: 0.11111111 | M48: 0.11111111 | O48: =K48*$P$15 -> 0.055555556 | P48: =L48*$P$15 -> 0.055555556 | Q48: =M48*$P$15 -> 0.055555556
...

Sheet 3 шаг 
R2: ρ | S2: 1
R3: Δt | S3: 0.03
D4: X | E4: Y | R4: γ | S4: 0.1 | U4: вязкость
C5: 1 | D5: 0 | E5: 0
C6: 2 | D6: 1 | E6: 0
C7: 3 | D7: 1 | E7: 1
C8: 4 | D8: 0 | E8: 1
B10: 1 треугольник | F10: X | G10: Y
E11: 1 | F11: =D5 -> 0 | G11: =E5 -> 0
B12: одна точка интегрирования | E12: 2 | F12: =D6 -> 1 | G12: =E6 -> 0
E13: 3 | F13: =D7 -> 1 | G13: =E7 -> 1
B14: ось | C14: координата т. интегр. | E14: производные функции формы | J14: матрица Якоби [J] | N14: detJ | P14: detJ* коэф | R14: один раз умножаем!!!!! | U14: {J]-1
B15: ξ | C15: =1/3 -> 0.33333333 | E15: -1 | F15: 1 | G15: 0 | J15: {=MMULT(E15:G16,F11:G13)} -> 1 | K15: 0 | N15: =MDETERM(J15:K16) -> 1 | P15: =N15*0.5 -> 0.5 | Q15: S | U15: {=MINVERSE(J15:K16)} -> 1 | V15: 0
B16: η | C16: =1/3 -> 0.33333333 | E16: -1 | F16: 0 | G16: 1 | J16: 1 | K16: 1 | U16: -1 | V16: 1
E19: N1 | F19: N2 | G19: N3 | I19: NT | K19: NT*N | O19: NT*N*detJ*коэф
E20: =1-C15-C16 -> 0.33333333 | F20: =C15 -> 0.33333333 | G20: =C16 -> 0.33333333 | I20: {=TRANSPOSE(E20:G20)} -> 0.33333333 | K20: {=MMULT(I20:I22,E20:G20)} -> 0.11111111 | L20: 0.11111111 | M20: 0.11111111 | O20: =K20*$P$15 -> 0.055555556 | P20: =L20*$P$15 -> 0.055555556 | Q20: =M20*$P$15 -> 0.055555556
I21: 0.33333333 | K21: 0.11111111 | L21: 0.11111111 | M21: 0.11111111 | O21: =K21*$P$15 -> 0.055555556 | P21: =L21*$P$15 -> 0.055555556 | Q21: =M21*$P$15 -> 0.055555556
E22: =SUM(E20:G20) -> 1 | I22: 0.33333333 | K22: 0.11111111 | L22: 0.11111111 | M22: 0.11111111 | O22: =K22*$P$15 -> 0.055555556 | P22: =L22*$P$15 -> 0.055555556 | Q22: =M22*$P$15 -> 0.055555556
V23: K1
E24: {=MMULT($U$15:$V$16,E15:E16)} -> -1 | F24: {=MMULT($U$15:$V$16,F15:F16)} -> 1 | G24: {=MMULT($U$15:$V$16,G15:G16)} -> 0 | O24: {=TRANSPOSE(E24:G25)} -> -1 | P24: 0 | R24: {=MMULT(O24:P26,E24:G25)} -> 1 | S24: -1 | T24: 0 | V24: =R24*$P$15 -> 0.5 | W24: =S24*$P$15 -> -0.5 | X24: =T24*$P$15 -> 0
E25: 0 | F25: -1 | G25: 1 | O25: 1 | P25: -1 | R25: -1 | S25: 2 | T25: -1 | V25: =R25*$P$15 -> -0.5 | W25: =S25*$P$15 -> 1 | X25: =T25*$P$15 -> -0.5
O26: 0 | P26: 1 | R26: 0 | S26: -1 | T26: 1 | V26: =R26*$P$15 -> 0 | W26: =S26*$P$15 -> -0.5 | X26: =T26*$P$15 -> 0.5
E27: B | L27: BT | P27: BT*B | W27: BT*B*det[J]*коэф
E28: =E24 -> -1 | F28: 0 | G28: =F24 -> 1 | H28: 0 | I28: =G24 -> 0 | J28: 0 | L28: {=TRANSPOSE(E28:J30)} -> -1 | M28: 0 | N28: 0 | P28: {=MMULT(L28:N33,E28:J30)} -> 1 | Q28: 0 | R28: -1 | S28: 0 | T28: 0 | U28: 0 | W28: =P28*$P$15 -> 0.5 | X28: =Q28*$P$15 -> 0 | Y28: =R28*$P$15 -> -0.5 | Z28: =S28*$P$15 -> 0 | AA28: =T28*$P$15 -> 0 | AB28: =U28*$P$15 -> 0
E29: 0 | F29: =E25 -> 0 | G29: 0 | H29: =F25 -> -1 | I29: 0 | J29: =G25 -> 1 | L29: 0 | M29: 0 | N29: -1 | P29: 0 | Q29: 1 | R29: 1 | S29: -1 | T29: -1 | U29: 0 | W29: =P29*$P$15 -> 0 | X29: =Q29*$P$15 -> 0.5 | Y29: =R29*$P$15 -> 0.5 | Z29: =S29*$P$15 -> -0.5 | AA29: =T29*$P$15 -> -0.5 | AB29: =U29*$P$15 -> 0
E30: =E25 -> 0 | F30: =E24 -> -1 | G30: =F25 -> -1 | H30: =F24 -> 1 | I30: =G25 -> 1 | J30: =G24 -> 0 | L30: 1 | M30: 0 | N30: -1 | P30: -1 | Q30: 1 | R30: 2 | S30: -1 | T30: -1 | U30: 0 | W30: =P30*$P$15 -> -0.5 | X30: =Q30*$P$15 -> 0.5 | Y30: =R30*$P$15 -> 1 | Z30: =S30*$P$15 -> -0.5 | AA30: =T30*$P$15 -> -0.5 | AB30: =U30*$P$15 -> 0
L31: 0 | M31: -1 | N31: 1 | P31: 0 | Q31: -1 | R31: -1 | S31: 2 | T31: 1 | U31: -1 | W31: =P31*$P$15 -> 0 | X31: =Q31*$P$15 -> -0.5 | Y31: =R31*$P$15 -> -0.5 | Z31: =S31*$P$15 -> 1 | AA31: =T31*$P$15 -> 0.5 | AB31: =U31*$P$15 -> -0.5
L32: 0 | M32: 0 | N32: 1 | P32: 0 | Q32: -1 | R32: -1 | S32: 1 | T32: 1 | U32: 0 | W32: =P32*$P$15 -> 0 | X32: =Q32*$P$15 -> -0.5 | Y32: =R32*$P$15 -> -0.5 | Z32: =S32*$P$15 -> 0.5 | AA32: =T32*$P$15 -> 0.5 | AB32: =U32*$P$15 -> 0
L33: 0 | M33: 1 | N33: 0 | P33: 0 | Q33: 0 | R33: 0 | S33: -1 | T33: 0 | U33: 1 | W33: =P33*$P$15 -> 0 | X33: =Q33*$P$15 -> 0 | Y33: =R33*$P$15 -> 0 | Z33: =S33*$P$15 -> -0.5 | AA33: =T33*$P$15 -> 0 | AB33: =U33*$P$15 -> 0.5
B36: 2 треугольник | F36: X | G36: Y
E37: 1 | F37: =D5 -> 0 | G37: =E5 -> 0
B38: одна точка интегрирования | E38: 3 | F38: =D7 -> 1 | G38: =E7 -> 1
E39: 4 | F39: =D8 -> 0 | G39: =E8 -> 1
B40: ось | C40: координата т. интегр. | E40: производные функции формы | J40: матрица Якоби [J] | N40: detJ | P40: detJ* коэф | R40: один раз умножаем!!!!! | U40: {J]-1
B41: ξ | C41: =1/3 -> 0.33333333 | E41: -1 | F41: 1 | G41: 0 | J41: {=MMULT(E41:G42,F37:G39)} -> 1 | K41: 1 | N41: =MDETERM(J41:K42) -> 1 | P41: =N41*0.5 -> 0.5 | Q41: S | U41: {=MINVERSE(J41:K42)} -> 1 | V41: -1
B42: η | C42: =1/3 -> 0.33333333 | E42: -1 | F42: 0 | G42: 1 | J42: 0 | K42: 1 | U42: 0 | V42: 1
E45: N1 | F45: N2 | G45: N3 | I45: NT | K45: NT*N | O45: NT*N*detJ*коэф
E46: =1-C41-C42 -> 0.33333333 | F46: =C41 -> 0.33333333 | G46: =C42 -> 0.33333333 | I46: {=TRANSPOSE(E46:G46)} -> 0.33333333 | K46: {=MMULT(I46:I48,E46:G46)} -> 0.11111111 | L46: 0.11111111 | M46: 0.11111111 | O46: =K46*$P$15 -> 0.055555556 | P46: =L46*$P$15 -> 0.055555556 | Q46: =M46*$P$15 -> 0.055555556
I47: 0.33333333 | K47: 0.11111111 | L47: 0.11111111 | M47: 0.11111111 | O47: =K47*$P$15 -> 0.055555556 | P47: =L47*$P$15 -> 0.055555556 | Q47: =M47*$P$15 -> 0.055555556
E48: =SUM(E46:G46) -> 1 | I48: 0.33333333 | K48: 0.11111111 | L48: 0.11111111 | M48: 0.11111111 | O48: =K48*$P$15 -> 0.055555556 | P48: =L48*$P$15 -> 0.055555556 | Q48: =M48*$P$15 -> 0.055555556
...

Sheet 4 шаг 
R2: ρ | S2: 1
R3: Δt | S3: 0.03
D4: X | E4: Y | R4: γ | S4: 0.1 | U4: вязкость
C5: 1 | D5: 0 | E5: 0
C6: 2 | D6: 1 | E6: 0
C7: 3 | D7: 1 | E7: 1
C8: 4 | D8: 0 | E8: 1
B10: 1 треугольник | F10: X | G10: Y
E11: 1 | F11: =D5 -> 0 | G11: =E5 -> 0
B12: одна точка интегрирования | E12: 2 | F12: =D6 -> 1 | G12: =E6 -> 0
E13: 3 | F13: =D7 -> 1 | G13: =E7 -> 1
B14: ось | C14: координата т. интегр. | E14: производные функции формы | J14: матрица Якоби [J] | N14: detJ | P14: detJ* коэф | R14: один раз умножаем!!!!! | U14: {J]-1
B15: ξ | C15: =1/3 -> 0.33333333 | E15: -1 | F15: 1 | G15: 0 | J15: {=MMULT(E15:G16,F11:G13)} -> 1 | K15: 0 | N15: =MDETERM(J15:K16) -> 1 | P15: =N15*0.5 -> 0.5 | Q15: S | U15: {=MINVERSE(J15:K16)} -> 1 | V15: 0
B16: η | C16: =1/3 -> 0.33333333 | E16: -1 | F16: 0 | G16: 1 | J16: 1 | K16: 1 | U16: -1 | V16: 1
E19: N1 | F19: N2 | G19: N3 | I19: NT | K19: NT*N | O19: NT*N*detJ*коэф
E20: =1-C15-C16 -> 0.33333333 | F20: =C15 -> 0.33333333 | G20: =C16 -> 0.33333333 | I20: {=TRANSPOSE(E20:G20)} -> 0.33333333 | K20: {=MMULT(I20:I22,E20:G20)} -> 0.11111111 | L20: 0.11111111 | M20: 0.11111111 | O20: =K20*$P$15 -> 0.055555556 | P20: =L20*$P$15 -> 0.055555556 | Q20: =M20*$P$15 -> 0.055555556
I21: 0.33333333 | K21: 0.11111111 | L21: 0.11111111 | M21: 0.11111111 | O21: =K21*$P$15 -> 0.055555556 | P21: =L21*$P$15 -> 0.055555556 | Q21: =M21*$P$15 -> 0.055555556
E22: =SUM(E20:G20) -> 1 | I22: 0.33333333 | K22: 0.11111111 | L22: 0.11111111 | M22: 0.11111111 | O22: =K22*$P$15 -> 0.055555556 | P22: =L22*$P$15 -> 0.055555556 | Q22: =M22*$P$15 -> 0.055555556
V23: K1
E24: {=MMULT($U$15:$V$16,E15:E16)} -> -1 | F24: {=MMULT($U$15:$V$16,F15:F16)} -> 1 | G24: {=MMULT($U$15:$V$16,G15:G16)} -> 0 | O24: {=TRANSPOSE(E24:G25)} -> -1 | P24: 0 | R24: {=MMULT(O24:P26,E24:G25)} -> 1 | S24: -1 | T24: 0 | V24: =R24*$P$15 -> 0.5 | W24: =S24*$P$15 -> -0.5 | X24: =T24*$P$15 -> 0
E25: 0 | F25: -1 | G25: 1 | O25: 1 | P25: -1 | R25: -1 | S25: 2 | T25: -1 | V25: =R25*$P$15 -> -0.5 | W25: =S25*$P$15 -> 1 | X25: =T25*$P$15 -> -0.5
O26: 0 | P26: 1 | R26: 0 | S26: -1 | T26: 1 | V26: =R26*$P$15 -> 0 | W26: =S26*$P$15 -> -0.5 | X26: =T26*$P$15 -> 0.5
E27: B | L27: BT | P27: BT*B | W27: BT*B*det[J]*коэф
E28: =E24 -> -1 | F28: 0 | G28: =F24 -> 1 | H28: 0 | I28: =G24 -> 0 | J28: 0 | L28: {=TRANSPOSE(E28:J30)} -> -1 | M28: 0 | N28: 0 | P28: {=MMULT(L28:N33,E28:J30)} -> 1 | Q28: 0 | R28: -1 | S28: 0 | T28: 0 | U28: 0 | W28: =P28*$P$15 -> 0.5 | X28: =Q28*$P$15 -> 0 | Y28: =R28*$P$15 -> -0.5 | Z28: =S28*$P$15 -> 0 | AA28: =T28*$P$15 -> 0 | AB28: =U28*$P$15 -> 0
E29: 0 | F29: =E25 -> 0 | G29: 0 | H29: =F25 -> -1 | I29: 0 | J29: =G25 -> 1 | L29: 0 | M29: 0 | N29: -1 | P29: 0 | Q29: 1 | R29: 1 | S29: -1 | T29: -1 | U29: 0 | W29: =P29*$P$15 -> 0 | X29: =Q29*$P$15 -> 0.5 | Y29: =R29*$P$15 -> 0.5 | Z29: =S29*$P$15 -> -0.5 | AA29: =T29*$P$15 -> -0.5 | AB29: =U29*$P$15 -> 0
E30: =E25 -> 0 | F30: =E24 -> -1 | G30: =F25 -> -1 | H30: =F24 -> 1 | I30: =G25 -> 1 | J30: =G24 -> 0 | L30: 1 | M30: 0 | N30: -1 | P30: -1 | Q30: 1 | R30: 2 | S30: -1 | T30: -1 | U30: 0 | W30: =P30*$P$15 -> -0.5 | X30: =Q30*$P$15 -> 0.5 | Y30: =R30*$P$15 -> 1 | Z30: =S30*$P$15 -> -0.5 | AA30: =T30*$P$15 -> -0.5 | AB30: =U30*$P$15 -> 0
L31: 0 | M31: -1 | N31: 1 | P31: 0 | Q31: -1 | R31: -1 | S31: 2 | T31: 1 | U31: -1 | W31: =P31*$P$15 -> 0 | X31: =Q31*$P$15 -> -0.5 | Y31: =R31*$P$15 -> -0.5 | Z31: =S31*$P$15 -> 1 | AA31: =T31*$P$15 -> 0.5 | AB31: =U31*$P$15 -> -0.5
L32: 0 | M32: 0 | N32: 1 | P32: 0 | Q32: -1 | R32: -1 | S32: 1 | T32: 1 | U32: 0 | W32: =P32*$P$15 -> 0 | X32: =Q32*$P$15 -> -0.5 | Y32: =R32*$P$15 -> -0.5 | Z32: =S32*$P$15 -> 0.5 | AA32: =T32*$P$15 -> 0.5 | AB32: =U32*$P$15 -> 0
L33: 0 | M33: 1 | N33: 0 | P33: 0 | Q33: 0 | R33: 0 | S33: -1 | T33: 0 | U33: 1 | W33: =P33*$P$15 -> 0 | X33: =Q33*$P$15 -> 0 | Y33: =R33*$P$15 -> 0 | Z33: =S33*$P$15 -> -0.5 | AA33: =T33*$P$15 -> 0 | AB33: =U33*$P$15 -> 0.5
B36: 2 треугольник | F36: X | G36: Y
E37: 1 | F37: =D5 -> 0 | G37: =E5 -> 0
B38: одна точка интегрирования | E38: 3 | F38: =D7 -> 1 | G38: =E7 -> 1
E39: 4 | F39: =D8 -> 0 | G39: =E8 -> 1
B40: ось | C40: координата т. интегр. | E40: производные функции формы | J40: матрица Якоби [J] | N40: detJ | P40: detJ* коэф | R40: один раз умножаем!!!!! | U40: {J]-1
B41: ξ | C41: =1/3 -> 0.33333333 | E41: -1 | F41: 1 | G41: 0 | J41: {=MMULT(E41:G42,F37:G39)} -> 1 | K41: 1 | N41: =MDETERM(J41:K42) -> 1 | P41: =N41*0.5 -> 0.5 | Q41: S | U41: {=MINVERSE(J41:K42)} -> 1 | V41: -1
B42: η | C42: =1/3 -> 0.33333333 | E42: -1 | F42: 0 | G42: 1 | J42: 0 | K42: 1 | U42: 0 | V42: 1
E45: N1 | F45: N2 | G45: N3 | I45: NT | K45: NT*N | O45: NT*N*detJ*коэф
E46: =1-C41-C42 -> 0.33333333 | F46: =C41 -> 0.33333333 | G46: =C42 -> 0.33333333 | I46: {=TRANSPOSE(E46:G46)} -> 0.33333333 | K46: {=MMULT(I46:I48,E46:G46)} -> 0.11111111 | L46: 0.11111111 | M46: 0.11111111 | O46: =K46*$P$15 -> 0.055555556 | P46: =L46*$P$15 -> 0.055555556 | Q46: =M46*$P$15 -> 0.055555556
I47: 0.33333333 | K47: 0.11111111 | L47: 0.11111111 | M47: 0.11111111 | O47: =K47*$P$15 -> 0.055555556 | P47: =L47*$P$15 -> 0.055555556 | Q47: =M47*$P$15 -> 0.055555556
E48: =SUM(E46:G46) -> 1 | I48: 0.33333333 | K48: 0.11111111 | L48: 0.11111111 | M48: 0.11111111 | O48: =K48*$P$15 -> 0.055555556 | P48: =L48*$P$15 -> 0.055555556 | Q48: =M48*$P$15 -> 0.055555556
...

Sheet 5 шаг 
R2: ρ | S2: 1
R3: Δt | S3: 0.03
D4: X | E4: Y | R4: γ | S4: 0.1 | U4: вязкость
C5: 1 | D5: 0 | E5: 0
C6: 2 | D6: 1 | E6: 0
C7: 3 | D7: 1 | E7: 1
C8: 4 | D8: 0 | E8: 1
B10: 1 треугольник | F10: X | G10: Y
E11: 1 | F11: =D5 -> 0 | G11: =E5 -> 0
B12: одна точка интегрирования | E12: 2 | F12: =D6 -> 1 | G12: =E6 -> 0
E13: 3 | F13: =D7 -> 1 | G13: =E7 -> 1
B14: ось | C14: координата т. интегр. | E14: производные функции формы | J14: матрица Якоби [J] | N14: detJ | P14: detJ* коэф | R14: один раз умножаем!!!!! | U14: {J]-1
B15: ξ | C15: =1/3 -> 0.33333333 | E15: -1 | F15: 1 | G15: 0 | J15: {=MMULT(E15:G16,F11:G13)} -> 1 | K15: 0 | N15: =MDETERM(J15:K16) -> 1 | P15: =N15*0.5 -> 0.5 | Q15: S | U15: {=MINVERSE(J15:K16)} -> 1 | V15: 0
B16: η | C16: =1/3 -> 0.33333333 | E16: -1 | F16: 0 | G16: 1 | J16: 1 | K16: 1 | U16: -1 | V16: 1
E19: N1 | F19: N2 | G19: N3 | I19: NT | K19: NT*N | O19: NT*N*detJ*коэф
E20: =1-C15-C16 -> 0.33333333 | F20: =C15 -> 0.33333333 | G20: =C16 -> 0.33333333 | I20: {=TRANSPOSE(E20:G20)} -> 0.33333333 | K20: {=MMULT(I20:I22,E20:G20)} -> 0.11111111 | L20: 0.11111111 | M20: 0.11111111 | O20: =K20*$P$15 -> 0.055555556 | P20: =L20*$P$15 -> 0.055555556 | Q20: =M20*$P$15 -> 0.055555556
I21: 0.33333333 | K21: 0.11111111 | L21: 0.11111111 | M21: 0.11111111 | O21: =K21*$P$15 -> 0.055555556 | P21: =L21*$P$15 -> 0.055555556 | Q21: =M21*$P$15 -> 0.055555556
E22: =SUM(E20:G20) -> 1 | I22: 0.33333333 | K22: 0.11111111 | L22: 0.11111111 | M22: 0.11111111 | O22: =K22*$P$15 -> 0.055555556 | P22: =L22*$P$15 -> 0.055555556 | Q22: =M22*$P$15 -> 0.055555556
V23: K1
E24: {=MMULT($U$15:$V$16,E15:E16)} -> -1 | F24: {=MMULT($U$15:$V$16,F15:F16)} -> 1 | G24: {=MMULT($U$15:$V$16,G15:G16)} -> 0 | O24: {=TRANSPOSE(E24:G25)} -> -1 | P24: 0 | R24: {=MMULT(O24:P26,E24:G25)} -> 1 | S24: -1 | T24: 0 | V24: =R24*$P$15 -> 0.5 | W24: =S24*$P$15 -> -0.5 | X24: =T24*$P$15 -> 0
E25: 0 | F25: -1 | G25: 1 | O25: 1 | P25: -1 | R25: -1 | S25: 2 | T25: -1 | V25: =R25*$P$15 -> -0.5 | W25: =S25*$P$15 -> 1 | X25: =T25*$P$15 -> -0.5
O26: 0 | P26: 1 | R26: 0 | S26: -1 | T26: 1 | V26: =R26*$P$15 -> 0 | W26: =S26*$P$15 -> -0.5 | X26: =T26*$P$15 -> 0.5
E27: B | L27: BT | P27: BT*B | W27: BT*B*det[J]*коэф
E28: =E24 -> -1 | F28: 0 | G28: =F24 -> 1 | H28: 0 | I28: =G24 -> 0 | J28: 0 | L28: {=TRANSPOSE(E28:J30)} -> -1 | M28: 0 | N28: 0 | P28: {=MMULT(L28:N33,E28:J30)} -> 1 | Q28: 0 | R28: -1 | S28: 0 | T28: 0 | U28: 0 | W28: =P28*$P$15 -> 0.5 | X28: =Q28*$P$15 -> 0 | Y28: =R28*$P$15 -> -0.5 | Z28: =S28*$P$15 -> 0 | AA28: =T28*$P$15 -> 0 | AB28: =U28*$P$15 -> 0
E29: 0 | F29: =E25 -> 0 | G29: 0 | H29: =F25 -> -1 | I29: 0 | J29: =G25 -> 1 | L29: 0 | M29: 0 | N29: -1 | P29: 0 | Q29: 1 | R29: 1 | S29: -1 | T29: -1 | U29: 0 | W29: =P29*$P$15 -> 0 | X29: =Q29*$P$15 -> 0.5 | Y29: =R29*$P$15 -> 0.5 | Z29: =S29*$P$15 -> -0.5 | AA29: =T29*$P$15 -> -0.5 | AB29: =U29*$P$15 -> 0
E30: =E25 -> 0 | F30: =E24 -> -1 | G30: =F25 -> -1 | H30: =F24 -> 1 | I30: =G25 -> 1 | J30: =G24 -> 0 | L30: 1 | M30: 0 | N30: -1 | P30: -1 | Q30: 1 | R30: 2 | S30: -1 | T30: -1 | U30: 0 | W30: =P30*$P$15 -> -0.5 | X30: =Q30*$P$15 -> 0.5 | Y30: =R30*$P$15 -> 1 | Z30: =S30*$P$15 -> -0.5 | AA30: =T30*$P$15 -> -0.5 | AB30: =U30*$P$15 -> 0
L31: 0 | M31: -1 | N31: 1 | P31: 0 | Q31: -1 | R31: -1 | S31: 2 | T31: 1 | U31: -1 | W31: =P31*$P$15 -> 0 | X31: =Q31*$P$15 -> -0.5 | Y31: =R31*$P$15 -> -0.5 | Z31: =S31*$P$15 -> 1 | AA31: =T31*$P$15 -> 0.5 | AB31: =U31*$P$15 -> -0.5
L32: 0 | M32: 0 | N32: 1 | P32: 0 | Q32: -1 | R32: -1 | S32: 1 | T32: 1 | U32: 0 | W32: =P32*$P$15 -> 0 | X32: =Q32*$P$15 -> -0.5 | Y32: =R32*$P$15 -> -0.5 | Z32: =S32*$P$15 -> 0.5 | AA32: =T32*$P$15 -> 0.5 | AB32: =U32*$P$15 -> 0
L33: 0 | M33: 1 | N33: 0 | P33: 0 | Q33: 0 | R33: 0 | S33: -1 | T33: 0 | U33: 1 | W33: =P33*$P$15 -> 0 | X33: =Q33*$P$15 -> 0 | Y33: =R33*$P$15 -> 0 | Z33: =S33*$P$15 -> -0.5 | AA33: =T33*$P$15 -> 0 | AB33: =U33*$P$15 -> 0.5
B36: 2 треугольник | F36: X | G36: Y
E37: 1 | F37: =D5 -> 0 | G37: =E5 -> 0
B38: одна точка интегрирования | E38: 3 | F38: =D7 -> 1 | G38: =E7 -> 1
E39: 4 | F39: =D8 -> 0 | G39: =E8 -> 1
B40: ось | C40: координата т. интегр. | E40: производные функции формы | J40: матрица Якоби [J] | N40: detJ | P40: detJ* коэф | R40: один раз умножаем!!!!! | U40: {J]-1
B41: ξ | C41: =1/3 -> 0.33333333 | E41: -1 | F41: 1 | G41: 0 | J41: {=MMULT(E41:G42,F37:G39)} -> 1 | K41: 1 | N41: =MDETERM(J41:K42) -> 1 | P41: =N41*0.5 -> 0.5 | Q41: S | U41: {=MINVERSE(J41:K42)} -> 1 | V41: -1
B42: η | C42: =1/3 -> 0.33333333 | E42: -1 | F42: 0 | G42: 1 | J42: 0 | K42: 1 | U42: 0 | V42: 1
E45: N1 | F45: N2 | G45: N3 | I45: NT | K45: NT*N | O45: NT*N*detJ*коэф
E46: =1-C41-C42 -> 0.33333333 | F46: =C41 -> 0.33333333 | G46: =C42 -> 0.33333333 | I46: {=TRANSPOSE(E46:G46)} -> 0.33333333 | K46: {=MMULT(I46:I48,E46:G46)} -> 0.11111111 | L46: 0.11111111 | M46: 0.11111111 | O46: =K46*$P$15 -> 0.055555556 | P46: =L46*$P$15 -> 0.055555556 | Q46: =M46*$P$15 -> 0.055555556
I47: 0.33333333 | K47: 0.11111111 | L47: 0.11111111 | M47: 0.11111111 | O47: =K47*$P$15 -> 0.055555556 | P47: =L47*$P$15 -> 0.055555556 | Q47: =M47*$P$15 -> 0.055555556
E48: =SUM(E46:G46) -> 1 | I48: 0.33333333 | K48: 0.11111111 | L48: 0.11111111 | M48: 0.11111111 | O48: =K48*$P$15 -> 0.055555556 | P48: =L48*$P$15 -> 0.055555556 | Q48: =M48*$P$15 -> 0.055555556
...
